Workbook

Sheet Sheet1
A1: PR. 1 Fundamental Booster | C1: Student ID | D1: Name | E1: Math | F1: Science | G1: English | H1: Enrollment Date | I1: Grade (Math) | J1: Sales ID | K1: Product | L1: Region | M1: Salesperson | N1: Amount | O1: Date | P1: Discount Eligible? | Q1: Employee ID | R1: Name | S1: Department | T1: Salary | U1: Joining Date | V1: Years of Service
A2: Topics: - Relative & Absolute References, Formatting, Data Input - IF Formulas, Nested IFs, IF with AND/OR - COUNTIFS, SUMIFS, AVERAGEIFS - Lookup Functions (VLOOKUP, XLOOKUP, XMATCH) - INDEX/MATCH for dynamic searches - TEXT Functions for string manipulations - INDIRECT and OFFSET for dynamic references - Date/Time, Math Functions, FILTER function Main Tasks: 1. Apply IF formulas to classify student grades. 2. Use COUNTIFS to count students scoring above 60. 3. Use VLOOKUP to find a product price from sales data. 4. Apply XLOOKUP to fetch employee salaries dynamically. 5. Format and analyze date of joining in Employee data. 6. Use FILTER function to extract students with grades above 80. Deliverable: Complete the given worksheets by applying the required formulas in respective sheets. | C2: 1001 | D2: Student 1 | E2: 61 | F2: 48 | G2: 76 | H2: 43101 | I2: =IF(E2>=90,"A",IF(E2>=75,"B",IF(E2>=60,"C","F"))) -> C | J2: 2001 | K2: Keyboard | L2: South | M2: Person 1 | N2: 7048 | O2: 44927 | P2: =IF(OR(N2>40000,K2="Laptop"),"Yes","No") -> No | Q2: 3001 | R2: Employee 1 | S2: Finance | T2: 86766 | U2: 42005 | V2: =IF(U2>TODAY(),0,DATEDIF(U2,TODAY(),"Y")) -> 11
C3: 1002 | D3: Student 2 | E3: 78 | F3: 76 | G3: 70 | H3: 43281 | I3: =IF(E3>=90,"A",IF(E3>=75,"B",IF(E3>=60,"C","F"))) -> B | J3: 2002 | K3: Printer | L3: West | M3: Person 2 | N3: 17428 | O3: 44942 | P3: =IF(OR(N3>40000,K3="Laptop"),"Yes","No") -> No | Q3: 3002 | R3: Employee 2 | S3: Finance | T3: 31943 | U3: 42255 | V3: =IF(U3>TODAY(),0,DATEDIF(U3,TODAY(),"Y")) -> 10
C4: 1003 | D4: Student 3 | E4: 97 | F4: 60 | G4: 51 | H4: 43461 | I4: =IF(E4>=90,"A",IF(E4>=75,"B",IF(E4>=60,"C","F"))) -> A | J4: 2003 | K4: Mouse | L4: South | M4: Person 3 | N4: 23672 | O4: 44957 | P4: =IF(OR(N4>40000,K4="Laptop"),"Yes","No") -> No | Q4: 3003 | R4: Employee 3 | S4: HR | T4: 63374 | U4: 42505 | V4: =IF(U4>TODAY(),0,DATEDIF(U4,TODAY(),"Y")) -> 9
A5: Essential Tasks | C5: 1004 | D5: Student 4 | E5: 74 | F5: 55 | G5: 46 | H5: 43641 | I5: =IF(E5>=90,"A",IF(E5>=75,"B",IF(E5>=60,"C","F"))) -> C | J5: 2004 | K5: Printer | L5: East | M5: Person 4 | N5: 5264 | O5: 44972 | P5: =IF(OR(N5>40000,K5="Laptop"),"Yes","No") -> No | Q5: 3004 | R5: Employee 4 | S5: Finance | T5: 109972 | U5: 42755 | V5: =IF(U5>TODAY(),0,DATEDIF(U5,TODAY(),"Y")) -> 9
A6: Relative & Absolute Cell References, Formatting, and Data Input | C6: 1005 | D6: Student 5 | E6: 68 | F6: 74 | G6: 84 | H6: 43821 | I6: =IF(E6>=90,"A",IF(E6>=75,"B",IF(E6>=60,"C","F"))) -> C | J6: 2005 | K6: Keyboard | L6: North | M6: Person 5 | N6: 43388 | O6: 44987 | P6: =IF(OR(N6>40000,K6="Laptop"),"Yes","No") -> Yes | Q6: 3005 | R6: Employee 5 | S6: IT | T6: 54149 | U6: 43005 | V6: =IF(U6>TODAY(),0,DATEDIF(U6,TODAY(),"Y")) -> 8
A7: Enter and format data (bold, italic, currency, date, custom formats). | C7: 1006 | D7: Student 6 | E7: 80 | F7: 70 | G7: 65 | H7: 44001 | I7: =IF(E7>=90,"A",IF(E7>=75,"B",IF(E7>=60,"C","F"))) -> B | J7: 2006 | K7: Mouse | L7: North | M7: Person 6 | N7: 19757 | O7: 45002 | P7: =IF(OR(N7>40000,K7="Laptop"),"Yes","No") -> No | Q7: 3006 | R7: Employee 6 | S7: IT | T7: 78689 | U7: 43255 | V7: =IF(U7>TODAY(),0,DATEDIF(U7,TODAY(),"Y")) -> 7
A8: Use absolute ($A$1) and relative (A1) references in formulas. | C8: 1007 | D8: Student 7 | E8: 75 | F8: 47 | G8: 78 | H8: 44181 | I8: =IF(E8>=90,"A",IF(E8>=75,"B",IF(E8>=60,"C","F"))) -> B | J8: 2007 | K8: Mouse | L8: East | M8: Person 7 | N8: 32058 | O8: 45017 | P8: =IF(OR(N8>40000,K8="Laptop"),"Yes","No") -> No | Q8: 3007 | R8: Employee 7 | S8: Marketing | T8: 35960 | U8: 43505 | V8: =IF(U8>TODAY(),0,DATEDIF(U8,TODAY(),"Y")) -> 7
C9: 1008 | D9: Student 8 | E9: 94 | F9: 67 | G9: 64 | H9: 44361 | I9: =IF(E9>=90,"A",IF(E9>=75,"B",IF(E9>=60,"C","F"))) -> A | J9: 2008 | K9: Keyboard | L9: East | M9: Person 8 | N9: 46429 | O9: 45032 | P9: =IF(OR(N9>40000,K9="Laptop"),"Yes","No") -> Yes | Q9: 3008 | R9: Employee 8 | S9: IT | T9: 91659 | U9: 43755 | V9: =IF(U9>TODAY(),0,DATEDIF(U9,TODAY(),"Y")) -> 6
A10: Using IF Formula & Nesting IF Formulas | C10: 1009 | D10: Student 9 | E10: 41 | F10: 75 | G10: 56 | H10: 44541 | I10: =IF(E10>=90,"A",IF(E10>=75,"B",IF(E10>=60,"C","F"))) -> F | J10: 2009 | K10: Printer | L10: East | M10: Person 9 | N10: 19746 | O10: 45047 | P10: =IF(OR(N10>40000,K10="Laptop"),"Yes","No") -> No | Q10: 3009 | R10: Employee 9 | S10: IT | T10: 90423 | U10: 44005 | V10: =IF(U10>TODAY(),0,DATEDIF(U10,TODAY(),"Y")) -> 5
A11: Classify students' grades based on their scores. | C11: 1010 | D11: Student 10 | E11: 98 | F11: 54 | G11: 58 | H11: 44721 | I11: =IF(E11>=90,"A",IF(E11>=75,"B",IF(E11>=60,"C","F"))) -> A | J11: 2010 | K11: Keyboard | L11: South | M11: Person 10 | N11: 35185 | O11: 45062 | P11: =IF(OR(N11>40000,K11="Laptop"),"Yes","No") -> No | Q11: 3010 | R11: Employee 10 | S11: HR | T11: 107877 | U11: 44255 | V11: =IF(U11>TODAY(),0,DATEDIF(U11,TODAY(),"Y")) -> 5
A12: Compute discounts for sales based on price thresholds. | C12: 1011 | D12: Student 11 | E12: 73 | F12: 79 | G12: 53 | H12: 44901 | I12: =IF(E12>=90,"A",IF(E12>=75,"B",IF(E12>=60,"C","F"))) -> C | J12: 2011 | K12: Keyboard | L12: East | M12: Person 11 | N12: 33920 | O12: 45077 | P12: =IF(OR(N12>40000,K12="Laptop"),"Yes","No") -> No | Q12: 3011 | R12: Employee 11 | S12: Finance | T12: 107634 | U12: 44505 | V12: =IF(U12>TODAY(),0,DATEDIF(U12,TODAY(),"Y")) -> 4
C13: 1012 | D13: Student 12 | E13: 85 | F13: 89 | G13: 79 | H13: 45081 | I13: =IF(E13>=90,"A",IF(E13>=75,"B",IF(E13>=60,"C","F"))) -> B | J13: 2012 | K13: Monitor | L13: North | M13: Person 12 | N13: 35611 | O13: 45092 | P13: =IF(OR(N13>40000,K13="Laptop"),"Yes","No") -> No | Q13: 3012 | R13: Employee 12 | S13: Finance | T13: 35226 | U13: 44755 | V13: =IF(U13>TODAY(),0,DATEDIF(U13,TODAY(),"Y")) -> 3
A14: Using IF with AND/OR Formulas | C14: 1013 | D14: Student 13 | E14: 98 | F14: 90 | G14: 97 | H14: 45261 | I14: =IF(E14>=90,"A",IF(E14>=75,"B",IF(E14>=60,"C","F"))) -> A | J14: 2013 | K14: Laptop | L14: East | M14: Person 13 | N14: 15560 | O14: 45107 | P14: =IF(OR(N14>40000,K14="Laptop"),"Yes","No") -> Yes | Q14: 3013 | R14: Employee 13 | S14: HR | T14: 40872 | U14: 45005 | V14: =IF(U14>TODAY(),0,DATEDIF(U14,TODAY(),"Y")) -> 3
A15: Identify students who scored above 80 in both Math & Science using IF(AND(...)). | C15: 1014 | D15: Student 14 | E15: 93 | F15: 40 | G15: 44 | H15: 45441 | I15: =IF(E15>=90,"A",IF(E15>=75,"B",IF(E15>=60,"C","F"))) -> A | J15: 2014 | K15: Laptop | L15: South | M15: Person 14 | N15: 7283 | O15: 45122 | P15: =IF(OR(N15>40000,K15="Laptop"),"Yes","No") -> Yes | Q15: 3014 | R15: Employee 14 | S15: HR | T15: 55378 | U15: 45255 | V15: =IF(U15>TODAY(),0,DATEDIF(U15,TODAY(),"Y")) -> 2
A16: Determine whether a product is eligible for discount using IF(OR(...)). | C16: 1015 | D16: Student 15 | E16: 70 | F16: 51 | G16: 75 | H16: 45621 | I16: =IF(E16>=90,"A",IF(E16>=75,"B",IF(E16>=60,"C","F"))) -> C | J16: 2015 | K16: Laptop | L16: East | M16: Person 15 | N16: 15678 | O16: 45137 | P16: =IF(OR(N16>40000,K16="Laptop"),"Yes","No") -> Yes | Q16: 3015 | R16: Employee 15 | S16: HR | T16: 63297 | U16: 45505 | V16: =IF(U16>TODAY(),0,DATEDIF(U16,TODAY(),"Y")) -> 1
C17: 1016 | D17: Student 16 | E17: 98 | F17: 77 | G17: 60 | H17: 45801 | I17: =IF(E17>=90,"A",IF(E17>=75,"B",IF(E17>=60,"C","F"))) -> A | J17: 2016 | K17: Mouse | L17: East | M17: Person 16 | N17: 5277 | O17: 45152 | P17: =IF(OR(N17>40000,K17="Laptop"),"Yes","No") -> No | Q17: 3016 | R17: Employee 16 | S17: Finance | T17: 114173 | U17: 45755 | V17: =IF(U17>TODAY(),0,DATEDIF(U17,TODAY(),"Y")) -> 0
A18: COUNTIFS, SUMIFS, AVERAGEIFS | C18: 1017 | D18: Student 17 | E18: 66 | F18: 59 | G18: 40 | H18: 45981 | I18: =IF(E18>=90,"A",IF(E18>=75,"B",IF(E18>=60,"C","F"))) -> C | J18: 2017 | K18: Monitor | L18: North | M18: Person 17 | N18: 41871 | O18: 45167 | P18: =IF(OR(N18>40000,K18="Laptop"),"Yes","No") -> Yes | Q18: 3017 | R18: Employee 17 | S18: HR | T18: 86915 | U18: 46005 | V18: =IF(U18>TODAY(),0,DATEDIF(U18,TODAY(),"Y")) -> 0
A19: Count the number of students who scored above 50 in Math. | C19: 1018 | D19: Student 18 | E19: 82 | F19: 48 | G19: 79 | H19: 46161 | I19: =IF(E19>=90,"A",IF(E19>=75,"B",IF(E19>=60,"C","F"))) -> B | J19: 2018 | K19: Monitor | L19: West | M19: Person 18 | N19: 38161 | O19: 45182 | P19: =IF(OR(N19>40000,K19="Laptop"),"Yes","No") -> No | Q19: 3018 | R19: Employee 18 | S19: IT | T19: 116284 | U19: 46255 | V19: =IF(U19>TODAY(),0,DATEDIF(U19,TODAY(),"Y")) -> 0
A20: Sum total sales for a specific region and product. | C20: 1019 | D20: Student 19 | E20: 90 | F20: 78 | G20: 60 | H20: 46341 | I20: =IF(E20>=90,"A",IF(E20>=75,"B",IF(E20>=60,"C","F"))) -> A | J20: 2019 | K20: Mouse | L20: West | M20: Person 19 | N20: 30436 | O20: 45197 | P20: =IF(OR(N20>40000,K20="Laptop"),"Yes","No") -> No | Q20: 3019 | R20: Employee 19 | S20: Marketing | T20: 116283 | U20: 46505 | V20: =IF(U20>TODAY(),0,DATEDIF(U20,TODAY(),"Y")) -> 0
A21: Calculate the average score for students who scored above 60. | C21: 1020 | D21: Student 20 | E21: 83 | F21: 92 | G21: 55 | H21: 46521 | I21: =IF(E21>=90,"A",IF(E21>=75,"B",IF(E21>=60,"C","F"))) -> B | J21: 2020 | K21: Printer | L21: West | M21: Person 20 | N21: 33953 | O21: 45212 | P21: =IF(OR(N21>40000,K21="Laptop"),"Yes","No") -> No | Q21: 3020 | R21: Employee 20 | S21: Marketing | T21: 99924 | U21: 46755 | V21: =IF(U21>TODAY(),0,DATEDIF(U21,TODAY(),"Y")) -> 0
A23: VLOOKUP Function
A24: Fetch student names based on ID from a separate dataset.
A25: Retrieve product prices based on product codes.
A27: INDEX and MATCH Functions
A28: Find sales values for a specific salesperson in a specific month.
A29: Look up employee details dynamically without column restrictions.
A31: Excel TEXT Functions
A32: Extract the first name from full names using LEFT and FIND.
A33: Convert names to uppercase/lowercase using UPPER(), LOWER().
A35: XLOOKUP Function
A36: Search for salesperson performance based on flexible search criteria.
A37: Find employee salaries without worrying about sorted data.
... A58: Quick Summary (COUNTIFS / SUMIFS / AVERAGEIFS)
A59: Students scoring > 50 in Math (COUNTIFS) | B59: =COUNTIFS(E2:E21,">50") -> 19
A60: Avg Math score where Math > 60 (AVERAGEIFS) | B60: =AVERAGEIFS(E2:E21,E2:E21,">60") -> 82.263158
A61: Total East Keyboard sales (SUMIFS) | B61: =SUMIFS(N2:N21,L2:L21,"East",K2:K21,"Keyboard") -> 80349
A62: Count Laptop East sales (COUNTIFS) | B62: =COUNTIFS(K2:K21,"Laptop",L2:L21,"East") -> 2
A63: Avg IT Dept salary (AVERAGEIFS) | B63: =AVERAGEIFS(T2:T21,S2:S21,"IT") -> 86240.8

Sheet Sheet2

Sheet Main Tasks
A1: PR.1 Fundamental Booster — Main Tasks Deliverable
A2: All 6 required tasks solved with Excel formulas referencing the source data in Sheet1
A4: TASK 1 — Apply IF Formulas to Classify Student Grades (≥90→A | ≥75→B | ≥60→C | else→F)
A5: Student ID | B5: Name | C5: Math | D5: Science | E5: English | F5: Math Grade | G5: Science Grade | H5: English Grade | I5: Overall Grade | J5: Discount on Sales (IF)
A6: =Sheet1!C2 -> 1001 | B6: =Sheet1!D2 -> Student 1 | C6: =Sheet1!E2 -> 61 | D6: =Sheet1!F2 -> 48 | E6: =Sheet1!G2 -> 76 | F6: =IF(Sheet1!E2>=90,"A",IF(Sheet1!E2>=75,"B",IF(Sheet1!E2>=60,"C","F"))) -> C | G6: =IF(Sheet1!F2>=90,"A",IF(Sheet1!F2>=75,"B",IF(Sheet1!F2>=60,"C","F"))) -> F | H6: =IF(Sheet1!G2>=90,"A",IF(Sheet1!G2>=75,"B",IF(Sheet1!G2>=60,"C","F"))) -> B | I6: =IF(AVERAGE(Sheet1!E2:G2)>=90,"A",IF(AVERAGE(Sheet1!E2:G2)>=75,"B",IF(AVERAGE(Sheet1!E2:G2)>=60,"C","F"))) -> C | J6: =IF(Sheet1!N2>30000,"10% Discount","No Discount") -> No Discount
A7: =Sheet1!C3 -> 1002 | B7: =Sheet1!D3 -> Student 2 | C7: =Sheet1!E3 -> 78 | D7: =Sheet1!F3 -> 76 | E7: =Sheet1!G3 -> 70 | F7: =IF(Sheet1!E3>=90,"A",IF(Sheet1!E3>=75,"B",IF(Sheet1!E3>=60,"C","F"))) -> B | G7: =IF(Sheet1!F3>=90,"A",IF(Sheet1!F3>=75,"B",IF(Sheet1!F3>=60,"C","F"))) -> B | H7: =IF(Sheet1!G3>=90,"A",IF(Sheet1!G3>=75,"B",IF(Sheet1!G3>=60,"C","F"))) -> C | I7: =IF(AVERAGE(Sheet1!E3:G3)>=90,"A",IF(AVERAGE(Sheet1!E3:G3)>=75,"B",IF(AVERAGE(Sheet1!E3:G3)>=60,"C","F"))) -> C | J7: =IF(Sheet1!N3>30000,"10% Discount","No Discount") -> No Discount
A8: =Sheet1!C4 -> 1003 | B8: =Sheet1!D4 -> Student 3 | C8: =Sheet1!E4 -> 97 | D8: =Sheet1!F4 -> 60 | E8: =Sheet1!G4 -> 51 | F8: =IF(Sheet1!E4>=90,"A",IF(Sheet1!E4>=75,"B",IF(Sheet1!E4>=60,"C","F"))) -> A | G8: =IF(Sheet1!F4>=90,"A",IF(Sheet1!F4>=75,"B",IF(Sheet1!F4>=60,"C","F"))) -> C | H8: =IF(Sheet1!G4>=90,"A",IF(Sheet1!G4>=75,"B",IF(Sheet1!G4>=60,"C","F"))) -> F | I8: =IF(AVERAGE(Sheet1!E4:G4)>=90,"A",IF(AVERAGE(Sheet1!E4:G4)>=75,"B",IF(AVERAGE(Sheet1!E4:G4)>=60,"C","F"))) -> C | J8: =IF(Sheet1!N4>30000,"10% Discount","No Discount") -> No Discount
A9: =Sheet1!C5 -> 1004 | B9: =Sheet1!D5 -> Student 4 | C9: =Sheet1!E5 -> 74 | D9: =Sheet1!F5 -> 55 | E9: =Sheet1!G5 -> 46 | F9: =IF(Sheet1!E5>=90,"A",IF(Sheet1!E5>=75,"B",IF(Sheet1!E5>=60,"C","F"))) -> C | G9: =IF(Sheet1!F5>=90,"A",IF(Sheet1!F5>=75,"B",IF(Sheet1!F5>=60,"C","F"))) -> F | H9: =IF(Sheet1!G5>=90,"A",IF(Sheet1!G5>=75,"B",IF(Sheet1!G5>=60,"C","F"))) -> F | I9: =IF(AVERAGE(Sheet1!E5:G5)>=90,"A",IF(AVERAGE(Sheet1!E5:G5)>=75,"B",IF(AVERAGE(Sheet1!E5:G5)>=60,"C","F"))) -> F | J9: =IF(Sheet1!N5>30000,"10% Discount","No Discount") -> No Discount
A10: =Sheet1!C6 -> 1005 | B10: =Sheet1!D6 -> Student 5 | C10: =Sheet1!E6 -> 68 | D10: =Sheet1!F6 -> 74 | E10: =Sheet1!G6 -> 84 | F10: =IF(Sheet1!E6>=90,"A",IF(Sheet1!E6>=75,"B",IF(Sheet1!E6>=60,"C","F"))) -> C | G10: =IF(Sheet1!F6>=90,"A",IF(Sheet1!F6>=75,"B",IF(Sheet1!F6>=60,"C","F"))) -> C | H10: =IF(Sheet1!G6>=90,"A",IF(Sheet1!G6>=75,"B",IF(Sheet1!G6>=60,"C","F"))) -> B | I10: =IF(AVERAGE(Sheet1!E6:G6)>=90,"A",IF(AVERAGE(Sheet1!E6:G6)>=75,"B",IF(AVERAGE(Sheet1!E6:G6)>=60,"C","F"))) -> B | J10: =IF(Sheet1!N6>30000,"10% Discount","No Discount") -> 10% Discount
A11: =Sheet1!C7 -> 1006 | B11: =Sheet1!D7 -> Student 6 | C11: =Sheet1!E7 -> 80 | D11: =Sheet1!F7 -> 70 | E11: =Sheet1!G7 -> 65 | F11: =IF(Sheet1!E7>=90,"A",IF(Sheet1!E7>=75,"B",IF(Sheet1!E7>=60,"C","F"))) -> B | G11: =IF(Sheet1!F7>=90,"A",IF(Sheet1!F7>=75,"B",IF(Sheet1!F7>=60,"C","F"))) -> C | H11: =IF(Sheet1!G7>=90,"A",IF(Sheet1!G7>=75,"B",IF(Sheet1!G7>=60,"C","F"))) -> C | I11: =IF(AVERAGE(Sheet1!E7:G7)>=90,"A",IF(AVERAGE(Sheet1!E7:G7)>=75,"B",IF(AVERAGE(Sheet1!E7:G7)>=60,"C","F"))) -> C | J11: =IF(Sheet1!N7>30000,"10% Discount","No Discount") -> No Discount
A12: =Sheet1!C8 -> 1007 | B12: =Sheet1!D8 -> Student 7 | C12: =Sheet1!E8 -> 75 | D12: =Sheet1!F8 -> 47 | E12: =Sheet1!G8 -> 78 | F12: =IF(Sheet1!E8>=90,"A",IF(Sheet1!E8>=75,"B",IF(Sheet1!E8>=60,"C","F"))) -> B | G12: =IF(Sheet1!F8>=90,"A",IF(Sheet1!F8>=75,"B",IF(Sheet1!F8>=60,"C","F"))) -> F | H12: =IF(Sheet1!G8>=90,"A",IF(Sheet1!G8>=75,"B",IF(Sheet1!G8>=60,"C","F"))) -> B | I12: =IF(AVERAGE(Sheet1!E8:G8)>=90,"A",IF(AVERAGE(Sheet1!E8:G8)>=75,"B",IF(AVERAGE(Sheet1!E8:G8)>=60,"C","F"))) -> C | J12: =IF(Sheet1!N8>30000,"10% Discount","No Discount") -> 10% Discount
A13: =Sheet1!C9 -> 1008 | B13: =Sheet1!D9 -> Student 8 | C13: =Sheet1!E9 -> 94 | D13: =Sheet1!F9 -> 67 | E13: =Sheet1!G9 -> 64 | F13: =IF(Sheet1!E9>=90,"A",IF(Sheet1!E9>=75,"B",IF(Sheet1!E9>=60,"C","F"))) -> A | G13: =IF(Sheet1!F9>=90,"A",IF(Sheet1!F9>=75,"B",IF(Sheet1!F9>=60,"C","F"))) -> C | H13: =IF(Sheet1!G9>=90,"A",IF(Sheet1!G9>=75,"B",IF(Sheet1!G9>=60,"C","F"))) -> C | I13: =IF(AVERAGE(Sheet1!E9:G9)>=90,"A",IF(AVERAGE(Sheet1!E9:G9)>=75,"B",IF(AVERAGE(Sheet1!E9:G9)>=60,"C","F"))) -> B | J13: =IF(Sheet1!N9>30000,"10% Discount","No Discount") -> 10% Discount
A14: =Sheet1!C10 -> 1009 | B14: =Sheet1!D10 -> Student 9 | C14: =Sheet1!E10 -> 41 | D14: =Sheet1!F10 -> 75 | E14: =Sheet1!G10 -> 56 | F14: =IF(Sheet1!E10>=90,"A",IF(Sheet1!E10>=75,"B",IF(Sheet1!E10>=60,"C","F"))) -> F | G14: =IF(Sheet1!F10>=90,"A",IF(Sheet1!F10>=75,"B",IF(Sheet1!F10>=60,"C","F"))) -> B | H14: =IF(Sheet1!G10>=90,"A",IF(Sheet1!G10>=75,"B",IF(Sheet1!G10>=60,"C","F"))) -> F | I14: =IF(AVERAGE(Sheet1!E10:G10)>=90,"A",IF(AVERAGE(Sheet1!E10:G10)>=75,"B",IF(AVERAGE(Sheet1!E10:G10)>=60,"C","F"))) -> F | J14: =IF(Sheet1!N10>30000,"10% Discount","No Discount") -> No Discount
A15: =Sheet1!C11 -> 1010 | B15: =Sheet1!D11 -> Student 10 | C15: =Sheet1!E11 -> 98 | D15: =Sheet1!F11 -> 54 | E15: =Sheet1!G11 -> 58 | F15: =IF(Sheet1!E11>=90,"A",IF(Sheet1!E11>=75,"B",IF(Sheet1!E11>=60,"C","F"))) -> A | G15: =IF(Sheet1!F11>=90,"A",IF(Sheet1!F11>=75,"B",IF(Sheet1!F11>=60,"C","F"))) -> F | H15: =IF(Sheet1!G11>=90,"A",IF(Sheet1!G11>=75,"B",IF(Sheet1!G11>=60,"C","F"))) -> F | I15: =IF(AVERAGE(Sheet1!E11:G11)>=90,"A",IF(AVERAGE(Sheet1!E11:G11)>=75,"B",IF(AVERAGE(Sheet1!E11:G11)>=60,"C","F"))) -> C | J15: =IF(Sheet1!N11>30000,"10% Discount","No Discount") -> 10% Discount
A16: =Sheet1!C12 -> 1011 | B16: =Sheet1!D12 -> Student 11 | C16: =Sheet1!E12 -> 73 | D16: =Sheet1!F12 -> 79 | E16: =Sheet1!G12 -> 53 | F16: =IF(Sheet1!E12>=90,"A",IF(Sheet1!E12>=75,"B",IF(Sheet1!E12>=60,"C","F"))) -> C | G16: =IF(Sheet1!F12>=90,"A",IF(Sheet1!F12>=75,"B",IF(Sheet1!F12>=60,"C","F"))) -> B | H16: =IF(Sheet1!G12>=90,"A",IF(Sheet1!G12>=75,"B",IF(Sheet1!G12>=60,"C","F"))) -> F | I16: =IF(AVERAGE(Sheet1!E12:G12)>=90,"A",IF(AVERAGE(Sheet1!E12:G12)>=75,"B",IF(AVERAGE(Sheet1!E12:G12)>=60,"C","F"))) -> C | J16: =IF(Sheet1!N12>30000,"10% Discount","No Discount") -> 10% Discount
A17: =Sheet1!C13 -> 1012 | B17: =Sheet1!D13 -> Student 12 | C17: =Sheet1!E13 -> 85 | D17: =Sheet1!F13 -> 89 | E17: =Sheet1!G13 -> 79 | F17: =IF(Sheet1!E13>=90,"A",IF(Sheet1!E13>=75,"B",IF(Sheet1!E13>=60,"C","F"))) -> B | G17: =IF(Sheet1!F13>=90,"A",IF(Sheet1!F13>=75,"B",IF(Sheet1!F13>=60,"C","F"))) -> B | H17: =IF(Sheet1!G13>=90,"A",IF(Sheet1!G13>=75,"B",IF(Sheet1!G13>=60,"C","F"))) -> B | I17: =IF(AVERAGE(Sheet1!E13:G13)>=90,"A",IF(AVERAGE(Sheet1!E13:G13)>=75,"B",IF(AVERAGE(Sheet1!E13:G13)>=60,"C","F"))) -> B | J17: =IF(Sheet1!N13>30000,"10% Discount","No Discount") -> 10% Discount
... A25: =Sheet1!C21 -> 1020 | B25: =Sheet1!D21 -> Student 20 | C25: =Sheet1!E21 -> 83 | D25: =Sheet1!F21 -> 92 | E25: =Sheet1!G21 -> 55 | F25: =IF(Sheet1!E21>=90,"A",IF(Sheet1!E21>=75,"B",IF(Sheet1!E21>=60,"C","F"))) -> B | G25: =IF(Sheet1!F21>=90,"A",IF(Sheet1!F21>=75,"B",IF(Sheet1!F21>=60,"C","F"))) -> A | H25: =IF(Sheet1!G21>=90,"A",IF(Sheet1!G21>=75,"B",IF(Sheet1!G21>=60,"C","F"))) -> F | I25: =IF(AVERAGE(Sheet1!E21:G21)>=90,"A",IF(AVERAGE(Sheet1!E21:G21)>=75,"B",IF(AVERAGE(Sheet1!E21:G21)>=60,"C","F"))) -> B | J25: =IF(Sheet1!N21>30000,"10% Discount","No Discount") -> 10% Discount
A27: TASK 2 — Use COUNTIFS to Count Students Scoring Above 60 (per subject & combined)
A28: Metric | B28: Formula | C28: Result | D28: Metric | E28: Formula | F28: Result | G28: Notes
A29: Math > 60 | B29: '=COUNTIFS(Sheet1!E2:E21,">60") | C29: =COUNTIFS(Sheet1!E2:E21,">60") -> 19 | D29: Science > 60 | E29: '=COUNTIFS(Sheet1!F2:F21,">60") | F29: =COUNTIFS(Sheet1!F2:F21,">60") -> 11 | G29: Count students where that subject score exceeds 60
A30: English > 60 | B30: '=COUNTIFS(Sheet1!G2:G21,">60") | C30: =COUNTIFS(Sheet1!G2:G21,">60") -> 10 | D30: Math AND Science >60 | E30: '=COUNTIFS(Sheet1!E2:E21,">60",Sheet1!F2:F21,">60") | F30: =COUNTIFS(Sheet1!E2:E21,">60",Sheet1!F2:F21,">60") -> 10 | G30: COUNTIFS with two criteria (AND logic)
A31: Math > 80 | B31: '=COUNTIFS(Sheet1!E2:E21,">80") | C31: =COUNTIFS(Sheet1!E2:E21,">80") -> 10 | D31: All 3 subjects > 60 | E31: '=COUNTIFS(Sheet1!E2:E21,">60",Sheet1!F2:F21,">60",Sheet1!G2:G21,">60") | F31: =COUNTIFS(Sheet1!E2:E21,">60",Sheet1!F2:F21,">60",Sheet1!G2:G21,">60") -> 6 | G31: All three subjects above 60 simultaneously
A32: Avg score > 60 | B32: '=COUNTIFS(Sheet1!E2:E21,">50") | C32: =COUNTIFS(Sheet1!E2:E21,">50") -> 19 | D32: IT Dept employees | E32: '=COUNTIFS(Sheet1!S2:S21,"IT") | F32: =COUNTIFS(Sheet1!S2:S21,"IT") -> 5 | G32: COUNTIFS on non-numeric data (department)
A34: TASK 3 — Use VLOOKUP to Find Product & Amount from Sales Data
A35: Lookup: Sales ID | B35: VLOOKUP — Product | C35: Result | D35: VLOOKUP — Region | E35: Result | F35: VLOOKUP — Salesperson | G35: Result | H35: VLOOKUP — Amount | I35: Result | J35: Notes
A36: 2001 | B36: '=VLOOKUP(2001,Sheet1!$J$2:$N$21,2,0) | C36: =VLOOKUP(2001,Sheet1!$J$2:$N$21,2,0) -> Keyboard | D36: '=VLOOKUP(2001,Sheet1!$J$2:$N$21,3,0) | E36: =VLOOKUP(2001,Sheet1!$J$2:$N$21,3,0) -> South | F36: '=VLOOKUP(2001,Sheet1!$J$2:$N$21,4,0) | G36: =VLOOKUP(2001,Sheet1!$J$2:$N$21,4,0) -> Person 1 | H36: '=VLOOKUP(2001,Sheet1!$J$2:$N$21,5,0) | I36: =VLOOKUP(2001,Sheet1!$J$2:$N$21,5,0) -> 7048 | J36: VLOOKUP(ID, $J$2:$N$21, col, 0) — col 2=Prod,3=Region,4=Person,5=Amt
A37: 2005 | B37: '=VLOOKUP(2005,Sheet1!$J$2:$N$21,2,0) | C37: =VLOOKUP(2005,Sheet1!$J$2:$N$21,2,0) -> Keyboard | D37: '=VLOOKUP(2005,Sheet1!$J$2:$N$21,3,0) | E37: =VLOOKUP(2005,Sheet1!$J$2:$N$21,3,0) -> North | F37: '=VLOOKUP(2005,Sheet1!$J$2:$N$21,4,0) | G37: =VLOOKUP(2005,Sheet1!$J$2:$N$21,4,0) -> Person 5 | H37: '=VLOOKUP(2005,Sheet1!$J$2:$N$21,5,0) | I37: =VLOOKUP(2005,Sheet1!$J$2:$N$21,5,0) -> 43388 | J37: VLOOKUP(ID, $J$2:$N$21, col, 0) — col 2=Prod,3=Region,4=Person,5=Amt
A38: 2009 | B38: '=VLOOKUP(2009,Sheet1!$J$2:$N$21,2,0) | C38: =VLOOKUP(2009,Sheet1!$J$2:$N$21,2,0) -> Printer | D38: '=VLOOKUP(2009,Sheet1!$J$2:$N$21,3,0) | E38: =VLOOKUP(2009,Sheet1!$J$2:$N$21,3,0) -> East | F38: '=VLOOKUP(2009,Sheet1!$J$2:$N$21,4,0) | G38: =VLOOKUP(2009,Sheet1!$J$2:$N$21,4,0) -> Person 9 | H38: '=VLOOKUP(2009,Sheet1!$J$2:$N$21,5,0) | I38: =VLOOKUP(2009,Sheet1!$J$2:$N$21,5,0) -> 19746 | J38: VLOOKUP(ID, $J$2:$N$21, col, 0) — col 2=Prod,3=Region,4=Person,5=Amt
A39: 2013 | B39: '=VLOOKUP(2013,Sheet1!$J$2:$N$21,2,0) | C39: =VLOOKUP(2013,Sheet1!$J$2:$N$21,2,0) -> Laptop | D39: '=VLOOKUP(2013,Sheet1!$J$2:$N$21,3,0) | E39: =VLOOKUP(2013,Sheet1!$J$2:$N$21,3,0) -> East | F39: '=VLOOKUP(2013,Sheet1!$J$2:$N$21,4,0) | G39: =VLOOKUP(2013,Sheet1!$J$2:$N$21,4,0) -> Person 13 | H39: '=VLOOKUP(2013,Sheet1!$J$2:$N$21,5,0) | I39: =VLOOKUP(2013,Sheet1!$J$2:$N$21,5,0) -> 15560 | J39: VLOOKUP(ID, $J$2:$N$21, col, 0) — col 2=Prod,3=Region,4=Person,5=Amt
A40: 2017 | B40: '=VLOOKUP(2017,Sheet1!$J$2:$N$21,2,0) | C40: =VLOOKUP(2017,Sheet1!$J$2:$N$21,2,0) -> Monitor | D40: '=VLOOKUP(2017,Sheet1!$J$2:$N$21,3,0) | E40: =VLOOKUP(2017,Sheet1!$J$2:$N$21,3,0) -> North | F40: '=VLOOKUP(2017,Sheet1!$J$2:$N$21,4,0) | G40: =VLOOKUP(2017,Sheet1!$J$2:$N$21,4,0) -> Person 17 | H40: '=VLOOKUP(2017,Sheet1!$J$2:$N$21,5,0) | I40: =VLOOKUP(2017,Sheet1!$J$2:$N$21,5,0) -> 41871 | J40: VLOOKUP(ID, $J$2:$N$21, col, 0) — col 2=Prod,3=Region,4=Person,5=Amt
A41: 2020 | B41: '=VLOOKUP(2020,Sheet1!$J$2:$N$21,2,0) | C41: =VLOOKUP(2020,Sheet1!$J$2:$N$21,2,0) -> Printer | D41: '=VLOOKUP(2020,Sheet1!$J$2:$N$21,3,0) | E41: =VLOOKUP(2020,Sheet1!$J$2:$N$21,3,0) -> West | F41: '=VLOOKUP(2020,Sheet1!$J$2:$N$21,4,0) | G41: =VLOOKUP(2020,Sheet1!$J$2:$N$21,4,0) -> Person 20 | H41: '=VLOOKUP(2020,Sheet1!$J$2:$N$21,5,0) | I41: =VLOOKUP(2020,Sheet1!$J$2:$N$21,5,0) -> 33953 | J41: VLOOKUP(ID, $J$2:$N$21, col, 0) — col 2=Prod,3=Region,4=Person,5=Amt
A43: TASK 4 — Apply XLOOKUP to Fetch Employee Salaries Dynamically (via INDEX/MATCH for compatibility)
A44: Employee Name | B44: XLOOKUP Formula (Excel 365) | C44: Department | D44: Salary Result | E44: INDEX/MATCH Equiv. | F44: Salary (I/M) | G44: Notes
A45: Employee 1 | B45: '=XLOOKUP("Employee 1",Sheet1!$R$2:$R$21,Sheet1!$T$2:$T$21) | C45: =INDEX(Sheet1!$S$2:$S$21,MATCH("Employee 1",Sheet1!$R$2:$R$21,0)) -> Finance | D45: =INDEX(Sheet1!$T$2:$T$21,MATCH("Employee 1",Sheet1!$R$2:$R$21,0)) -> 86766 | E45: '=INDEX($T$2:$T$21,MATCH("Employee 1",$R$2:$R$21,0)) | F45: =INDEX(Sheet1!$T$2:$T$21,MATCH("Employee 1",Sheet1!$R$2:$R$21,0)) -> 86766 | G45: XLOOKUP searches lookup_array & returns result_array value — no col index needed
A46: Employee 3 | B46: '=XLOOKUP("Employee 3",Sheet1!$R$2:$R$21,Sheet1!$T$2:$T$21) | C46: =INDEX(Sheet1!$S$2:$S$21,MATCH("Employee 3",Sheet1!$R$2:$R$21,0)) -> HR | D46: =INDEX(Sheet1!$T$2:$T$21,MATCH("Employee 3",Sheet1!$R$2:$R$21,0)) -> 63374 | E46: '=INDEX($T$2:$T$21,MATCH("Employee 3",$R$2:$R$21,0)) | F46: =INDEX(Sheet1!$T$2:$T$21,MATCH("Employee 3",Sheet1!$R$2:$R$21,0)) -> 63374 | G46: XLOOKUP searches lookup_array & returns result_array value — no col index needed
A47: Employee 5 | B47: '=XLOOKUP("Employee 5",Sheet1!$R$2:$R$21,Sheet1!$T$2:$T$21) | C47: =INDEX(Sheet1!$S$2:$S$21,MATCH("Employee 5",Sheet1!$R$2:$R$21,0)) -> IT | D47: =INDEX(Sheet1!$T$2:$T$21,MATCH("Employee 5",Sheet1!$R$2:$R$21,0)) -> 54149 | E47: '=INDEX($T$2:$T$21,MATCH("Employee 5",$R$2:$R$21,0)) | F47: =INDEX(Sheet1!$T$2:$T$21,MATCH("Employee 5",Sheet1!$R$2:$R$21,0)) -> 54149 | G47: XLOOKUP searches lookup_array & returns result_array value — no col index needed
A48: Employee 7 | B48: '=XLOOKUP("Employee 7",Sheet1!$R$2:$R$21,Sheet1!$T$2:$T$21) | C48: =INDEX(Sheet1!$S$2:$S$21,MATCH("Employee 7",Sheet1!$R$2:$R$21,0)) -> Marketing | D48: =INDEX(Sheet1!$T$2:$T$21,MATCH("Employee 7",Sheet1!$R$2:$R$21,0)) -> 35960 | E48: '=INDEX($T$2:$T$21,MATCH("Employee 7",$R$2:$R$21,0)) | F48: =INDEX(Sheet1!$T$2:$T$21,MATCH("Employee 7",Sheet1!$R$2:$R$21,0)) -> 35960 | G48: XLOOKUP searches lookup_array & returns result_array value — no col index needed
A49: Employee 9 | B49: '=XLOOKUP("Employee 9",Sheet1!$R$2:$R$21,Sheet1!$T$2:$T$21) | C49: =INDEX(Sheet1!$S$2:$S$21,MATCH("Employee 9",Sheet1!$R$2:$R$21,0)) -> IT | D49: =INDEX(Sheet1!$T$2:$T$21,MATCH("Employee 9",Sheet1!$R$2:$R$21,0)) -> 90423 | E49: '=INDEX($T$2:$T$21,MATCH("Employee 9",$R$2:$R$21,0)) | F49: =INDEX(Sheet1!$T$2:$T$21,MATCH("Employee 9",Sheet1!$R$2:$R$21,0)) -> 90423 | G49: XLOOKUP searches lookup_array & returns result_array value — no col index needed
A50: Employee 11 | B50: '=XLOOKUP("Employee 11",Sheet1!$R$2:$R$21,Sheet1!$T$2:$T$21) | C50: =INDEX(Sheet1!$S$2:$S$21,MATCH("Employee 11",Sheet1!$R$2:$R$21,0)) -> Finance | D50: =INDEX(Sheet1!$T$2:$T$21,MATCH("Employee 11",Sheet1!$R$2:$R$21,0)) -> 107634 | E50: '=INDEX($T$2:$T$21,MATCH("Employee 11",$R$2:$R$21,0)) | F50: =INDEX(Sheet1!$T$2:$T$21,MATCH("Employee 11",Sheet1!$R$2:$R$21,0)) -> 107634 | G50: XLOOKUP searches lookup_array & returns result_array value — no col index needed
A51: Employee 13 | B51: '=XLOOKUP("Employee 13",Sheet1!$R$2:$R$21,Sheet1!$T$2:$T$21) | C51: =INDEX(Sheet1!$S$2:$S$21,MATCH("Employee 13",Sheet1!$R$2:$R$21,0)) -> HR | D51: =INDEX(Sheet1!$T$2:$T$21,MATCH("Employee 13",Sheet1!$R$2:$R$21,0)) -> 40872 | E51: '=INDEX($T$2:$T$21,MATCH("Employee 13",$R$2:$R$21,0)) | F51: =INDEX(Sheet1!$T$2:$T$21,MATCH("Employee 13",Sheet1!$R$2:$R$21,0)) -> 40872 | G51: XLOOKUP searches lookup_array & returns result_array value — no col index needed
...

Sheet Solutions
A1: PR.1 Fundamental Booster – All Task Solutions
A3: 1. IF Formulas – Grade Classification (>= 90 A, >= 75 B, >= 60 C, else F)
A4: Student ID | B4: Name | C4: Math | D4: Science | E4: English | F4: Grade (Math)
A5: =Sheet1!C2 -> 1001 | B5: =Sheet1!D2 -> Student 1 | C5: =Sheet1!E2 -> 61 | D5: =Sheet1!F2 -> 48 | E5: =Sheet1!G2 -> 76 | F5: =IF(Sheet1!E2>=90,"A",IF(Sheet1!E2>=75,"B",IF(Sheet1!E2>=60,"C","F"))) -> C
A6: =Sheet1!C3 -> 1002 | B6: =Sheet1!D3 -> Student 2 | C6: =Sheet1!E3 -> 78 | D6: =Sheet1!F3 -> 76 | E6: =Sheet1!G3 -> 70 | F6: =IF(Sheet1!E3>=90,"A",IF(Sheet1!E3>=75,"B",IF(Sheet1!E3>=60,"C","F"))) -> B
A7: =Sheet1!C4 -> 1003 | B7: =Sheet1!D4 -> Student 3 | C7: =Sheet1!E4 -> 97 | D7: =Sheet1!F4 -> 60 | E7: =Sheet1!G4 -> 51 | F7: =IF(Sheet1!E4>=90,"A",IF(Sheet1!E4>=75,"B",IF(Sheet1!E4>=60,"C","F"))) -> A
A8: =Sheet1!C5 -> 1004 | B8: =Sheet1!D5 -> Student 4 | C8: =Sheet1!E5 -> 74 | D8: =Sheet1!F5 -> 55 | E8: =Sheet1!G5 -> 46 | F8: =IF(Sheet1!E5>=90,"A",IF(Sheet1!E5>=75,"B",IF(Sheet1!E5>=60,"C","F"))) -> C
A9: =Sheet1!C6 -> 1005 | B9: =Sheet1!D6 -> Student 5 | C9: =Sheet1!E6 -> 68 | D9: =Sheet1!F6 -> 74 | E9: =Sheet1!G6 -> 84 | F9: =IF(Sheet1!E6>=90,"A",IF(Sheet1!E6>=75,"B",IF(Sheet1!E6>=60,"C","F"))) -> C
A10: =Sheet1!C7 -> 1006 | B10: =Sheet1!D7 -> Student 6 | C10: =Sheet1!E7 -> 80 | D10: =Sheet1!F7 -> 70 | E10: =Sheet1!G7 -> 65 | F10: =IF(Sheet1!E7>=90,"A",IF(Sheet1!E7>=75,"B",IF(Sheet1!E7>=60,"C","F"))) -> B
A11: =Sheet1!C8 -> 1007 | B11: =Sheet1!D8 -> Student 7 | C11: =Sheet1!E8 -> 75 | D11: =Sheet1!F8 -> 47 | E11: =Sheet1!G8 -> 78 | F11: =IF(Sheet1!E8>=90,"A",IF(Sheet1!E8>=75,"B",IF(Sheet1!E8>=60,"C","F"))) -> B
A12: =Sheet1!C9 -> 1008 | B12: =Sheet1!D9 -> Student 8 | C12: =Sheet1!E9 -> 94 | D12: =Sheet1!F9 -> 67 | E12: =Sheet1!G9 -> 64 | F12: =IF(Sheet1!E9>=90,"A",IF(Sheet1!E9>=75,"B",IF(Sheet1!E9>=60,"C","F"))) -> A
A13: =Sheet1!C10 -> 1009 | B13: =Sheet1!D10 -> Student 9 | C13: =Sheet1!E10 -> 41 | D13: =Sheet1!F10 -> 75 | E13: =Sheet1!G10 -> 56 | F13: =IF(Sheet1!E10>=90,"A",IF(Sheet1!E10>=75,"B",IF(Sheet1!E10>=60,"C","F"))) -> F
A14: =Sheet1!C11 -> 1010 | B14: =Sheet1!D11 -> Student 10 | C14: =Sheet1!E11 -> 98 | D14: =Sheet1!F11 -> 54 | E14: =Sheet1!G11 -> 58 | F14: =IF(Sheet1!E11>=90,"A",IF(Sheet1!E11>=75,"B",IF(Sheet1!E11>=60,"C","F"))) -> A
A15: =Sheet1!C12 -> 1011 | B15: =Sheet1!D12 -> Student 11 | C15: =Sheet1!E12 -> 73 | D15: =Sheet1!F12 -> 79 | E15: =Sheet1!G12 -> 53 | F15: =IF(Sheet1!E12>=90,"A",IF(Sheet1!E12>=75,"B",IF(Sheet1!E12>=60,"C","F"))) -> C
A16: =Sheet1!C13 -> 1012 | B16: =Sheet1!D13 -> Student 12 | C16: =Sheet1!E13 -> 85 | D16: =Sheet1!F13 -> 89 | E16: =Sheet1!G13 -> 79 | F16: =IF(Sheet1!E13>=90,"A",IF(Sheet1!E13>=75,"B",IF(Sheet1!E13>=60,"C","F"))) -> B
... A24: =Sheet1!C21 -> 1020 | B24: =Sheet1!D21 -> Student 20 | C24: =Sheet1!E21 -> 83 | D24: =Sheet1!F21 -> 92 | E24: =Sheet1!G21 -> 55 | F24: =IF(Sheet1!E21>=90,"A",IF(Sheet1!E21>=75,"B",IF(Sheet1!E21>=60,"C","F"))) -> B
A26: 2. IF with AND – Students scoring > 80 in BOTH Math AND Science
A27: Student ID | B27: Name | C27: Math | D27: Science | E27: English | F27: Both > 80?
A28: =Sheet1!C2 -> 1001 | B28: =Sheet1!D2 -> Student 1 | C28: =Sheet1!E2 -> 61 | D28: =Sheet1!F2 -> 48 | E28: =Sheet1!G2 -> 76 | F28: =IF(AND(Sheet1!E2>80,Sheet1!F2>80),"Yes","No") -> No
A29: =Sheet1!C3 -> 1002 | B29: =Sheet1!D3 -> Student 2 | C29: =Sheet1!E3 -> 78 | D29: =Sheet1!F3 -> 76 | E29: =Sheet1!G3 -> 70 | F29: =IF(AND(Sheet1!E3>80,Sheet1!F3>80),"Yes","No") -> No
A30: =Sheet1!C4 -> 1003 | B30: =Sheet1!D4 -> Student 3 | C30: =Sheet1!E4 -> 97 | D30: =Sheet1!F4 -> 60 | E30: =Sheet1!G4 -> 51 | F30: =IF(AND(Sheet1!E4>80,Sheet1!F4>80),"Yes","No") -> No
A31: =Sheet1!C5 -> 1004 | B31: =Sheet1!D5 -> Student 4 | C31: =Sheet1!E5 -> 74 | D31: =Sheet1!F5 -> 55 | E31: =Sheet1!G5 -> 46 | F31: =IF(AND(Sheet1!E5>80,Sheet1!F5>80),"Yes","No") -> No
A32: =Sheet1!C6 -> 1005 | B32: =Sheet1!D6 -> Student 5 | C32: =Sheet1!E6 -> 68 | D32: =Sheet1!F6 -> 74 | E32: =Sheet1!G6 -> 84 | F32: =IF(AND(Sheet1!E6>80,Sheet1!F6>80),"Yes","No") -> No
A33: =Sheet1!C7 -> 1006 | B33: =Sheet1!D7 -> Student 6 | C33: =Sheet1!E7 -> 80 | D33: =Sheet1!F7 -> 70 | E33: =Sheet1!G7 -> 65 | F33: =IF(AND(Sheet1!E7>80,Sheet1!F7>80),"Yes","No") -> No
A34: =Sheet1!C8 -> 1007 | B34: =Sheet1!D8 -> Student 7 | C34: =Sheet1!E8 -> 75 | D34: =Sheet1!F8 -> 47 | E34: =Sheet1!G8 -> 78 | F34: =IF(AND(Sheet1!E8>80,Sheet1!F8>80),"Yes","No") -> No
A35: =Sheet1!C9 -> 1008 | B35: =Sheet1!D9 -> Student 8 | C35: =Sheet1!E9 -> 94 | D35: =Sheet1!F9 -> 67 | E35: =Sheet1!G9 -> 64 | F35: =IF(AND(Sheet1!E9>80,Sheet1!F9>80),"Yes","No") -> No
A36: =Sheet1!C10 -> 1009 | B36: =Sheet1!D10 -> Student 9 | C36: =Sheet1!E10 -> 41 | D36: =Sheet1!F10 -> 75 | E36: =Sheet1!G10 -> 56 | F36: =IF(AND(Sheet1!E10>80,Sheet1!F10>80),"Yes","No") -> No
A37: =Sheet1!C11 -> 1010 | B37: =Sheet1!D11 -> Student 10 | C37: =Sheet1!E11 -> 98 | D37: =Sheet1!F11 -> 54 | E37: =Sheet1!G11 -> 58 | F37: =IF(AND(Sheet1!E11>80,Sheet1!F11>80),"Yes","No") -> No
A38: =Sheet1!C12 -> 1011 | B38: =Sheet1!D12 -> Student 11 | C38: =Sheet1!E12 -> 73 | D38: =Sheet1!F12 -> 79 | E38: =Sheet1!G12 -> 53 | F38: =IF(AND(Sheet1!E12>80,Sheet1!F12>80),"Yes","No") -> No
A39: =Sheet1!C13 -> 1012 | B39: =Sheet1!D13 -> Student 12 | C39: =Sheet1!E13 -> 85 | D39: =Sheet1!F13 -> 89 | E39: =Sheet1!G13 -> 79 | F39: =IF(AND(Sheet1!E13>80,Sheet1!F13>80),"Yes","No") -> Yes
... A47: =Sheet1!C21 -> 1020 | B47: =Sheet1!D21 -> Student 20 | C47: =Sheet1!E21 -> 83 | D47: =Sheet1!F21 -> 92 | E47: =Sheet1!G21 -> 55 | F47: =IF(AND(Sheet1!E21>80,Sheet1!F21>80),"Yes","No") -> Yes
A49: 3. IF with OR – Discount Eligibility (Amount > 40000 OR Product = Laptop)
A50: Sales ID | B50: Product | C50: Region | D50: Salesperson | E50: Amount | F50: Discount Eligible?
A51: =Sheet1!J2 -> 2001 | B51: =Sheet1!K2 -> Keyboard | C51: =Sheet1!L2 -> South | D51: =Sheet1!M2 -> Person 1 | E51: =Sheet1!N2 -> 7048 | F51: =IF(OR(Sheet1!N2>40000,Sheet1!K2="Laptop"),"Yes","No") -> No
A52: =Sheet1!J3 -> 2002 | B52: =Sheet1!K3 -> Printer | C52: =Sheet1!L3 -> West | D52: =Sheet1!M3 -> Person 2 | E52: =Sheet1!N3 -> 17428 | F52: =IF(OR(Sheet1!N3>40000,Sheet1!K3="Laptop"),"Yes","No") -> No
A53: =Sheet1!J4 -> 2003 | B53: =Sheet1!K4 -> Mouse | C53: =Sheet1!L4 -> South | D53: =Sheet1!M4 -> Person 3 | E53: =Sheet1!N4 -> 23672 | F53: =IF(OR(Sheet1!N4>40000,Sheet1!K4="Laptop"),"Yes","No") -> No
A54: =Sheet1!J5 -> 2004 | B54: =Sheet1!K5 -> Printer | C54: =Sheet1!L5 -> East | D54: =Sheet1!M5 -> Person 4 | E54: =Sheet1!N5 -> 5264 | F54: =IF(OR(Sheet1!N5>40000,Sheet1!K5="Laptop"),"Yes","No") -> No
A55: =Sheet1!J6 -> 2005 | B55: =Sheet1!K6 -> Keyboard | C55: =Sheet1!L6 -> North | D55: =Sheet1!M6 -> Person 5 | E55: =Sheet1!N6 -> 43388 | F55: =IF(OR(Sheet1!N6>40000,Sheet1!K6="Laptop"),"Yes","No") -> Yes
A56: =Sheet1!J7 -> 2006 | B56: =Sheet1!K7 -> Mouse | C56: =Sheet1!L7 -> North | D56: =Sheet1!M7 -> Person 6 | E56: =Sheet1!N7 -> 19757 | F56: =IF(OR(Sheet1!N7>40000,Sheet1!K7="Laptop"),"Yes","No") -> No
A57: =Sheet1!J8 -> 2007 | B57: =Sheet1!K8 -> Mouse | C57: =Sheet1!L8 -> East | D57: =Sheet1!M8 -> Person 7 | E57: =Sheet1!N8 -> 32058 | F57: =IF(OR(Sheet1!N8>40000,Sheet1!K8="Laptop"),"Yes","No") -> No
...
